Workbook

Sheet RevenuesT2_Sankey
A1: Name | B1: 2024 ($Ms) | C1: Category | D1: Source
A2: Children's Services | B2: 972.67 | C2: Community and Social Services | D2: p 106/107
A3: Court Services | B3: 108.185 | C3: Community and Social Services | D3: p 106/108
A4: Economic Development and Culture | B4: 18.039 | C4: Community and Social Services | D4: p 106/109
A5: Fire Services | B5: 29.586 | C5: Community and Social Services | D5: p 106/110
A6: Toronto Paramedic Services | B6: 213.976 | C6: Community and Social Services | D6: p 106/111
A7: Seniors Services and Long-Term Care | B7: 315.87 | C7: Community and Social Services | D7: p 106/112
A8: Parks, Forestry & Recreation | B8: 173.116 | C8: Community and Social Services | D8: p 106/113
A9: Social Development, Finance & Administration | B9: 17.18 | C9: Community and Social Services | D9: p 106/114
A10: Toronto Employment & Social Services | B10: 1162.375 | C10: Community and Social Services | D10: p 106/115
A11: Toronto Shelter and Support Services | B11: 614.602 | C11: Community and Social Services | D11: p 106/116
A12: Engineering & Construction Services | B12: 79.664 | C12: Infrastructure Services | D12: p 106/117
A13: Municipal Licensing & Standards | B13: 58.732 | C13: Infrastructure Services | D13: p 106/118
... A73: Toronto Water | B73: 1553.226 | C73: Non Levy Operation | D73: p 106/178

Sheet ExpensesT2_Sankey
A1: Name | B1: 2024 ($full) | C1: 2024 ($M) | D1: Category | E1: Sankey | F1: Column1
A2: Children's Services | B2: 1066048000 | C2: =ExpensesT2_Sankey!$B2/1000000 -> 1066.048 | D2: Community and Social Services | E2: =CONCATENATE(ExpensesT2_Sankey!$D2," ","[",ExpensesT2_Sankey!$C2,"]"," ",ExpensesT2_Sankey!$A2) -> Community and Social Services [1066.048] Children's Services
A3: Court Services | B3: 37442000 | C3: =ExpensesT2_Sankey!$B3/1000000 -> 37.442 | D3: Community and Social Services | E3: =CONCATENATE(ExpensesT2_Sankey!$D3," ","[",ExpensesT2_Sankey!$C3,"]"," ",ExpensesT2_Sankey!$A3) -> Community and Social Services [37.442] Court Services
A4: Economic Development and Culture | B4: 102053000 | C4: =ExpensesT2_Sankey!$B4/1000000 -> 102.053 | D4: Community and Social Services | E4: =CONCATENATE(ExpensesT2_Sankey!$D4," ","[",ExpensesT2_Sankey!$C4,"]"," ",ExpensesT2_Sankey!$A4) -> Community and Social Services [102.053] Economic Development and Culture
A5: Fire Services | B5: 579616000 | C5: =ExpensesT2_Sankey!$B5/1000000 -> 579.616 | D5: Community and Social Services | E5: =CONCATENATE(ExpensesT2_Sankey!$D5," ","[",ExpensesT2_Sankey!$C5,"]"," ",ExpensesT2_Sankey!$A5) -> Community and Social Services [579.616] Fire Services
A6: Toronto Paramedic Services | B6: 325914000 | C6: =ExpensesT2_Sankey!$B6/1000000 -> 325.914 | D6: Community and Social Services | E6: =CONCATENATE(ExpensesT2_Sankey!$D6," ","[",ExpensesT2_Sankey!$C6,"]"," ",ExpensesT2_Sankey!$A6) -> Community and Social Services [325.914] Toronto Paramedic Services
A7: Seniors Services and Long-Term Care | B7: 380527000 | C7: =ExpensesT2_Sankey!$B7/1000000 -> 380.527 | D7: Community and Social Services | E7: =CONCATENATE(ExpensesT2_Sankey!$D7," ","[",ExpensesT2_Sankey!$C7,"]"," ",ExpensesT2_Sankey!$A7) -> Community and Social Services [380.527] Seniors Services and Long-Term Care
A8: Parks, Forestry & Recreation | B8: 537703000 | C8: =ExpensesT2_Sankey!$B8/1000000 -> 537.703 | D8: Community and Social Services | E8: =CONCATENATE(ExpensesT2_Sankey!$D8," ","[",ExpensesT2_Sankey!$C8,"]"," ",ExpensesT2_Sankey!$A8) -> Community and Social Services [537.703] Parks, Forestry & Recreation
A9: Social Development, Finance & Administration | B9: 128010000 | C9: =ExpensesT2_Sankey!$B9/1000000 -> 128.01 | D9: Community and Social Services | E9: =CONCATENATE(ExpensesT2_Sankey!$D9," ","[",ExpensesT2_Sankey!$C9,"]"," ",ExpensesT2_Sankey!$A9) -> Community and Social Services [128.01] Social Development, Finance & Administration
A10: Toronto Employment & Social Services | B10: 1244571000 | C10: =ExpensesT2_Sankey!$B10/1000000 -> 1244.571 | D10: Community and Social Services | E10: =CONCATENATE(ExpensesT2_Sankey!$D10," ","[",ExpensesT2_Sankey!$C10,"]"," ",ExpensesT2_Sankey!$A10) -> Community and Social Services [1244.571] Toronto Employment & Social Services
A11: Toronto Shelter and Support Services | B11: 843995000 | C11: =ExpensesT2_Sankey!$B11/1000000 -> 843.995 | D11: Community and Social Services | E11: =CONCATENATE(ExpensesT2_Sankey!$D11," ","[",ExpensesT2_Sankey!$C11,"]"," ",ExpensesT2_Sankey!$A11) -> Community and Social Services [843.995] Toronto Shelter and Support Services
A12: Engineering & Construction Services | B12: 85084000 | C12: =ExpensesT2_Sankey!$B12/1000000 -> 85.084 | D12: Infrastructure Services | E12: =CONCATENATE(ExpensesT2_Sankey!$D12," ","[",ExpensesT2_Sankey!$C12,"]"," ",ExpensesT2_Sankey!$A12) -> Infrastructure Services [85.084] Engineering & Construction Services
A13: Municipal Licensing & Standards | B13: 76939000 | C13: =ExpensesT2_Sankey!$B13/1000000 -> 76.939 | D13: Infrastructure Services | E13: =CONCATENATE(ExpensesT2_Sankey!$D13," ","[",ExpensesT2_Sankey!$C13,"]"," ",ExpensesT2_Sankey!$A13) -> Infrastructure Services [76.939] Municipal Licensing & Standards
... A33: Mayor's Office | B33: 3055000 | C33: =ExpensesT2_Sankey!$B33/1000000 -> 3.055 | D33: Other City Programs | E33: =CONCATENATE(ExpensesT2_Sankey!$D33," ","[",ExpensesT2_Sankey!$C33,"]"," ",ExpensesT2_Sankey!$A33) -> Other City Programs [3.055] Mayor's Office
A34: City Council | B34: #VALUE! | C34: =ExpensesT2_Sankey!$B34/1000000 -> #VALUE! | D34: Other City Programs | E34: =CONCATENATE(ExpensesT2_Sankey!$D34," ","[",ExpensesT2_Sankey!$C34,"]"," ",ExpensesT2_Sankey!$A34) -> #VALUE!
A35: Auditor General's Office | B35: 7781000 | C35: =ExpensesT2_Sankey!$B35/1000000 -> 7.781 | D35: Accountability Offices | E35: =CONCATENATE(ExpensesT2_Sankey!$D35," ","[",ExpensesT2_Sankey!$C35,"]"," ",ExpensesT2_Sankey!$A35) -> Accountability Offices [7.781] Auditor General's Office
A36: Integrity Commissioner's Office | B36: 774000 | C36: =ExpensesT2_Sankey!$B36/1000000 -> 0.774 | D36: Accountability Offices | E36: =CONCATENATE(ExpensesT2_Sankey!$D36," ","[",ExpensesT2_Sankey!$C36,"]"," ",ExpensesT2_Sankey!$A36) -> Accountability Offices [0.774] Integrity Commissioner's Office
A37: Office of the Lobbyist Registrar | B37: 931000 | C37: =ExpensesT2_Sankey!$B37/1000000 -> 0.931 | D37: Accountability Offices | E37: =CONCATENATE(ExpensesT2_Sankey!$D37," ","[",ExpensesT2_Sankey!$C37,"]"," ",ExpensesT2_Sankey!$A37) -> Accountability Offices [0.931] Office of the Lobbyist Registrar
A38: Office of the Ombudsman | B38: 3840000 | C38: =ExpensesT2_Sankey!$B38/1000000 -> 3.84 | D38: Accountability Offices | E38: =CONCATENATE(ExpensesT2_Sankey!$D38," ","[",ExpensesT2_Sankey!$C38,"]"," ",ExpensesT2_Sankey!$A38) -> Accountability Offices [3.84] Office of the Ombudsman
A39: Toronto Public Health | B39: 13326000 | C39: =ExpensesT2_Sankey!$B39/1000000 -> 13.326 | D39: Agencies | E39: =CONCATENATE(ExpensesT2_Sankey!$D39," ","[",ExpensesT2_Sankey!$C39,"]"," ",ExpensesT2_Sankey!$A39) -> Agencies [13.326] Toronto Public Health
A40: Toronto Public Library | B40: 248052000 | C40: =ExpensesT2_Sankey!$B40/1000000 -> 248.052 | D40: Agencies | E40: =CONCATENATE(ExpensesT2_Sankey!$D40," ","[",ExpensesT2_Sankey!$C40,"]"," ",ExpensesT2_Sankey!$A40) -> Agencies [248.052] Toronto Public Library
A41: Exhibition Place | B41: 254511000 | C41: =ExpensesT2_Sankey!$B41/1000000 -> 254.511 | D41: Agencies | E41: =CONCATENATE(ExpensesT2_Sankey!$D41," ","[",ExpensesT2_Sankey!$C41,"]"," ",ExpensesT2_Sankey!$A41) -> Agencies [254.511] Exhibition Place
A42: Heritage Toronto | B42: 67217000 | C42: =ExpensesT2_Sankey!$B42/1000000 -> 67.217 | D42: Agencies | E42: =CONCATENATE(ExpensesT2_Sankey!$D42," ","[",ExpensesT2_Sankey!$C42,"]"," ",ExpensesT2_Sankey!$A42) -> Agencies [67.217] Heritage Toronto
A43: To Live | B43: 1335000 | C43: =ExpensesT2_Sankey!$B43/1000000 -> 1.335 | D43: Agencies | E43: =CONCATENATE(ExpensesT2_Sankey!$D43," ","[",ExpensesT2_Sankey!$C43,"]"," ",ExpensesT2_Sankey!$A43) -> Agencies [1.335] To Live
A44: Toronto Zoo | B44: 39820000 | C44: =ExpensesT2_Sankey!$B44/1000000 -> 39.82 | D44: Agencies | E44: =CONCATENATE(ExpensesT2_Sankey!$D44," ","[",ExpensesT2_Sankey!$C44,"]"," ",ExpensesT2_Sankey!$A44) -> Agencies [39.82] Toronto Zoo
A45: Sankofa Square | B45: 65470000 | C45: =ExpensesT2_Sankey!$B45/1000000 -> 65.47 | D45: Agencies | E45: =CONCATENATE(ExpensesT2_Sankey!$D45," ","[",ExpensesT2_Sankey!$C45,"]"," ",ExpensesT2_Sankey!$A45) -> Agencies [65.47] Sankofa Square
A46: CreateTO | B46: 3831000 | C46: =ExpensesT2_Sankey!$B46/1000000 -> 3.831 | D46: Agencies | E46: =CONCATENATE(ExpensesT2_Sankey!$D46," ","[",ExpensesT2_Sankey!$C46,"]"," ",ExpensesT2_Sankey!$A46) -> Agencies [3.831] CreateTO
... A79: Toronto Water | B79: 503995000 | C79: =ExpensesT2_Sankey!$B79/1000000 -> 503.995 | D79: Non-Levy Operation | E79: =CONCATENATE(ExpensesT2_Sankey!$D79," ","[",ExpensesT2_Sankey!$C79,"]"," ",ExpensesT2_Sankey!$A79) -> Non-Levy Operation [503.995] Toronto Water
C80: =ExpensesT2_Sankey!$B80/1000000 -> 0
C81: =ExpensesT2_Sankey!$B81/1000000 -> 0
C82: =ExpensesT2_Sankey!$B82/1000000 -> 0
C83: =ExpensesT2_Sankey!$B83/1000000 -> 0
C84: =ExpensesT2_Sankey!$B84/1000000 -> 0
C85: =ExpensesT2_Sankey!$B85/1000000 -> 0
C86: =ExpensesT2_Sankey!$B86/1000000 -> 0
C87: =ExpensesT2_Sankey!$B87/1000000 -> 0

Sheet T1 Gross Expenditures
A1: (In $000's) | B1: 2024
B2: Budget | C2: Projection
A3: Community and Social Services | B3: 5258206 | C3: 5245881
A4: Infrastructure Services | B4: 690384 | C4: 699594
A5: Development & Growth Services | B5: 943881 | C5: 896295
A6: Corporate Services | B6: 552788 | C6: 553781
A7: Finance and Treasury Services | B7: 131330 | C7: 112051
A8: City Manager | B8: 88047 | C8: 85917
A9: Other City Programs | B9: 155983 | C9: 148453
A10: TOTAL - CITY OPERATIONS | B10: 7835113 | C10: 7755298
A11: TOTAL - AGENCIES | B11: 4766515 | C11: 4655087
A12: TOTAL - CITY OPERATIONS AND AGENCIES | B12: 12601627 | C12: 12410385
A13: Capital and Corporate Financing | B13: 1214738 | C13: 1201659
A14: Non-Program Expenditures | B14: 710883 | C14: 691576
... A23: TOTAL NON-LEVY OPERATING BUDGET | B23: 1060773 | C23: 1037494

Sheet T2 Gross Expenditures
A1: (In $000's) | B1: 2024
B2: Budget | C2: Projection
A3: Community and Social Services
A4: Children's Services | B4: 1104644 | C4: 1066048
A5: Court Services | B5: 39734 | C5: 37442
A6: Economic Development and Culture | B6: 103200 | C6: 102053
A7: Fire Services | B7: 562151 | C7: 579616
A8: Toronto Paramedic Services | B8: 351543 | C8: 325914
A9: Seniors Services and Long-Term Care | B9: 389683 | C9: 380527
A10: Parks, Forestry & Recreation | B10: 531017 | C10: 537703
A11: Social Development, Finance & Administration | B11: 130592 | C11: 128010
A12: Toronto Employment & Social Services | B12: 1199330 | C12: 1244571
A13: Toronto Shelter and Support Services | B13: 846313 | C13: 843995
A14: Sub-Total Community and Social Services | B14: 5258206 | C14: 5245881
A15: Infrastructure Services
A16: Engineering & Construction Services | B16: 86725 | C16: 85084
A17: Municipal Licensing & Standards | B17: 78919 | C17: 76939
A18: Toronto Emergency Management | B18: 6653 | C18: 6112
A19: Policy, Planning, Finance & Administration | B19: 23240 | C19: 22785
A20: Transit Expansion | B20: 11882 | C20: 7979
A21: Transportation Services | B21: 482965 | C21: 500696
A22: Sub-Total Infrastructure Services | B22: 690384 | C22: 699594
A23: Development & Growth Services
A24: City Planning | B24: 75039 | C24: 73246
A25: Toronto Building | B25: 82676 | C25: 67258
A26: Housing Secretariat | B26: 774845 | C26: 747511
A27: Development Review | B27: 11322 | C27: 8280
A28: Sub-Total Development & Growth Services | B28: 943881 | C28: 896295
A29: Corporate Services
A30: Corporate Real Estate Management | B30: 219421 | C30: 225783
A31: Customer Experience | B31: 24874 | C31: 24392
A32: Environment & Climate | B32: 22478 | C32: 19162
A33: Fleet Services | B33: 74915 | C33: 79066
A34: Technology Services | B34: 177724 | C34: 174141
A35: Office of the Chief Information Security Officer | B35: 33376 | C35: 31237
A36: Sub-Total Corporate Services | B36: 552788 | C36: 553781
A37: Finance and Treasury Services
A38: Office of the Chief Financial Officer and Treasurer | B38: 56040 | C38: 45003
A39: Financial Operations & Control | B39: 75290 | C39: 67048
A40: Sub-Total Finance and Treasury Services | B40: 131330 | C40: 112051
...

Sheet T1 Revenues
A2: City Operations | D2: 2024
A3: (In $000's) | D3: Budget | E3: Projection | F3: 2025 Total Budget | K3: Change from 2024 Budget
K4: Incr / (Dcr) | O4: %
A5: Community and Social Services | D5: 3628938 | E5: 3625599 | F5: 4395321 | K5: 766383 | O5: 0.211
A6: Infrastructure Services | D6: 391393 | E6: 387245 | F6: 453803 | K6: 62410 | O6: 0.159
A7: Development & Growth Services | D7: 444916 | E7: 418078 | F7: 440748 | K7: -4167 | O7: (0.9%)
A8: Corporate Services | D8: 204012 | E8: 208492 | F8: 232477 | K8: 28465 | O8: 0.14
A9: Finance and Treasury Services | D9: 68913 | E9: 58434 | F9: 79281 | K9: 10368 | O9: 0.15
A10: City Manager | D10: 17089 | E10: 16877 | F10: 65142 | K10: 48053 | O10: 2.812
A11: Other City Programs | D11: 46309 | E11: 41258 | F11: 51734 | K11: 5425 | O11: 0.117
A12: Accountability Offices | D12: 100 | E12: 53 | F12: 100 | O12: 0
A13: TOTAL - CITY OPERATIONS | D13: 4801669 | E13: 4756037 | F13: 5718606 | K13: 916937 | O13: 0.191
A14: TOTAL - AGENCIES | D14: 1950838 | E14: 1862255 | F14: 2062143 | K14: 111305 | O14: 0.057
A15: TOTAL - CITY OPERATIONS AND AGENCIES | D15: 6752508 | E15: 6618291 | F15: 7780749 | K15: 1028241 | O15: 0.152
A17: Corporate Accounts
A18: Capital & Corporate Financing | D18: 330860 | E18: 317781 | F18: 391053 | K18: 60193 | O18: 0.182
A19: Non-Program Expenditures | D19: 286878 | E19: 283308 | F19: 198068 | K19: -88809 | O19: (31.0%)
A20: Non-Program Revenues | D20: 2117917 | E20: 2297654 | F20: 2589520 | K20: 471604 | O20: 0.223
A21: TOTAL - CORPORATE ACCOUNTS | D21: 2746016 | E21: 2910256 | F21: 3189078 | K21: 443061 | O21: 0.161
A22: TOTAL LEVY OPERATING BUDGET BEFORE ASSESSMENT GROWTH AND TAX INCREASE | D22: 9498524 | E22: 9528547 | F22: 10969827 | K22: 1471303 | O22: 0.155
A23: TOTAL LEVY INCLUDING SCARBOROUGH SUBWAY EXTENSION LEVY AND CITY BUILDING FUND | D23: 9498524 | E23: 9528547 | F23: 10969827 | K23: 1471303 | O23: 0.155
A24: TOTAL NON LEVY OPERATING BUDGET | D24: 2135502 | E24: 2150226 | F24: 2 240 644 | K24: 105 142 | O24: 0.049
A25: TOTAL OPERATING BUDGET | D25: =SUM(D23,D24) -> 11634026 | E25: =SUM(E24,E22) -> 11678773

Sheet T2 Revenues
A1: (In $000's) | D1: 2024 | F1: 2025 Total Budget | K1: Change from 2024 Budget
D2: Budget | E2: Projection | K2: Incr / (Dcr) | O2: %
A3: Community and Social Services
A4: Children's Services | D4: 1009864 | E4: 972670 | F4: 1577695 | K4: 567832 | O4: 0.562
A5: Court Services | D5: 101749 | E5: 108185 | F5: 32433 | K5: -69316 | O5: (68.1%)
A6: Economic Development and Culture | D6: 19653 | E6: 18039 | F6: 16165 | K6: -3489 | O6: (17.8%)
A7: Fire Services | D7: 22845 | E7: 29586 | F7: 25874 | K7: 3028 | O7: 0.133
A8: Toronto Paramedic Services | D8: 238434 | E8: 213976 | F8: 241868 | K8: 3434 | O8: 0.014
A9: Seniors Services and Long-Term Care | D9: 308930 | E9: 315870 | F9: 331761 | K9: 22831 | O9: 0.074
A10: Parks, Forestry & Recreation | D10: 185748 | E10: 173116 | F10: 218897 | K10: 33149 | O10: 0.178
A11: Social Development, Finance & Administration | D11: 19446 | E11: 17180 | F11: 16806 | K11: -2640 | O11: (13.6%)
A12: Toronto Employment & Social Services | D12: 1117134 | E12: 1162375 | F12: 1277044 | K12: 159911 | O12: 0.143
A13: Toronto Shelter and Support Services | D13: 605135 | E13: 614602 | F13: 656778 | K13: 51643 | O13: 0.085
A14: Sub-Total Community and Social Services | D14: 3628938 | E14: 3625599 | F14: 4395321 | K14: 766383 | O14: 0.211
A15: Infrastructure Services
A16: Engineering & Construction Services | D16: 84814 | E16: 79664 | F16: 92442 | K16: 7629 | O16: 0.09
A17: Municipal Licensing & Standards | D17: 51396 | E17: 58732 | F17: 60731 | K17: 9335 | O17: 0.182
A18: Toronto Emergency Management | D18: 1406 | E18: 1307 | F18: 2977 | K18: 1571 | O18: 1.117
A19: Policy, Planning, Finance & Administration | D19: 17253 | E19: 17036 | F19: 21752 | K19: 4499 | O19: 0.261
A20: Transit Expansion | D20: 9188 | E20: 9922 | F20: 9386 | K20: 198 | O20: 0.022
A21: Transportation Services | D21: 227335 | E21: 220585 | F21: 266514 | K21: 39179 | O21: 0.172
A22: Sub-Total Infrastructure Services | D22: 391393 | E22: 387245 | F22: 453803 | K22: 62410 | O22: 0.159
A23: Development & Growth Services
A24: City Planning | D24: 64553 | E24: 51580 | F24: 63391 | K24: -1163 | O24: (1.8%)
A25: Toronto Building | D25: 98823 | E25: 99429 | F25: 107666 | K25: 8843 | O25: 0.089
A26: Housing Secretariat | D26: 270218 | E26: 258788 | F26: 260016 | K26: -10202 | O26: (3.8%)
A27: Development Review | D27: 11322 | E27: 8280 | F27: 9676
A28: Sub-Total Development & Growth Services | D28: 444916 | E28: 418078 | F28: 440748 | K28: -4167 | O28: (0.9%)
A29: Corporate Services
A30: Corporate Real Estate Management | D30: 96089 | E30: 102509 | F30: 108535 | K30: 12445 | O30: 0.13
A31: Customer Experience | D31: 9985 | E31: 9594 | F31: 9727 | K31: -258 | O31: (2.6%)
A32: Environment & Climate | D32: 7474 | E32: 4221 | F32: 9105 | K32: 1631 | O32: 0.218
A33: Fleet Services | D33: 39543 | E33: 43323 | F33: 44295 | K33: 4751 | O33: 0.12
A34: Technology Services | D34: 50356 | E34: 48427 | F34: 60215 | K34: 9859 | O34: 0.196
A35: Office of the Chief Information Security Officer | D35: 565 | E35: 418 | F35: 601 | K35: 36 | O35: 0.064
A36: Sub-Total Corporate Services | D36: 204012 | E36: 208492 | F36: 232477 | K36: 28465 | O36: 0.14
A37: Finance and Treasury Services
A38: Office of the Chief Financial Officer and Treasurer | D38: 23585 | E38: 16367 | F38: 25426 | K38: 1841 | O38: 0.078
A39: Financial Operations & Control | D39: 45328 | E39: 42066 | F39: 53855 | K39: 8527 | O39: 0.188
A40: Sub-Total Finance and Treasury Services | D40: 68913 | E40: 58434 | F40: 79281 | K40: 10368 | O40: 0.15
...

Sheet By Commitment Group
A1: Appendix 1.1.5 CITY OF TORONTO 2025 TOTAL OPERATING BUD ET SUMMARY BY COMMITMENT ITEM GROUP
K2: 2024 | P2: 2025
A3: (In $000's) | K3: Budget | P3: Budget
A4: Gross Expenditures
A5: Salaries And Benefits | K5: 6998850 | P5: 7633366
A6: Materials & Supplies | K6: 719489 | P6: 751644
A7: Equipment | K7: 70341 | P7: 80963
A8: Service And Rent | K8: 2937754 | P8: 3654972
A9: Contribution To Capital | K9: 1768 | P9: 1768
A10: Contribution To Reserves/Reserve Funds | K10: 735994 | P10: 868046
A11: Other Expenditures (inc Inter-Divisional Charges) | K11: 3338248 | P11: 3617700
A12: Rate Programs | K12: 2135502 | P12: 2240644
A13: Sub-Total Gross Expenditures | K13: 16937945 | P13: 18849103
A14: Revenues
A15: Provincial Subsidies (Note 1) | K15: 2927787 | P15: 3255238
A16: Federal Subsidies | K16: 984685 | P16: 1530780
A17: Other Subsidies | K17: 23978 | P17: 24924
A18: User Fees & Donations | K18: 1695003 | P18: 1845199
A19: Licences & Permits Revenue | K19: 135266 | P19: 162109
A20: Contribution From Reserves/Reserve Funds | K20: 1191984 | P20: 1300807
A21: Transfers From Capital | K21: 230750 | P21: 284382
A22: Sundry and Other Revenues (inc. Inter-Divisional Recoveries) | K22: 2309071 | P22: 2566388
A23: Rate Programs | K23: 2135502 | P23: 2240644
A24: Sub-Total Revenues | K24: 11634026 | P24: 13210471
A26: Net Expenditures (Note 2) | K26: 5303919 | P26: 5638632
A27: Notes: (1) The net amount for Provincial Gas Tax is included under Provincial Subsidies. (2) Total levy and non-Levy figures above are excluding Special Levy for Scarborough Subway and City Building Fund.
